Workbook

Sheet 업체정보
A1: 상호명 | B1: 주소 | C1: 업체연락처 | D1: 운동장카페 | E1: 동반 카페 | F1: 대형견카페 | G1: 동반 음식점 | H1: 동반 술집 | I1: 동반 펜션 | J1: 주차가능 | K1: 실내 동반 | L1: 테라스 동반 | M1: 호텔링 | N1: 유치원 | O1: 애견미용 | P1: 동반 조건 및 메모 | Q1: 지역
A2: 펫타리움 청담점 | B2: 서울 강남구 영동대로 725 6층 | C2: 0507-1403-1704 | D2: 1 | E2: 1 | F2: 0 | G2: 0 | H2: 0 | I2: 0 | J2: 1 | K2: 1 | L2: 1 | M2: 0 | N2: 0 | O2: 0 | Q2: =IF(LEN(TRIM(B2))=0,"",IFERROR(VLOOKUP(LEFT(TRIM(B2),FIND(" ",TRIM(B2)&" ")-1),작성안내!$D$4:$E$23,2,FALSE),LEFT(TRIM(B2),FIND(" ",TRIM(B2)&" ")-1))) -> 서울
A3: 니멍내멍 | B3: 경기 남양주시 불암산로 172 | C3: 0507-1345-7457 | D3: 1 | E3: 1 | F3: 0 | G3: 0 | H3: 0 | I3: 0 | J3: 1 | K3: 1 | L3: 1 | M3: 0 | N3: 0 | O3: 0 | Q3: =IF(LEN(TRIM(B3))=0,"",IFERROR(VLOOKUP(LEFT(TRIM(B3),FIND(" ",TRIM(B3)&" ")-1),작성안내!$D$4:$E$23,2,FALSE),LEFT(TRIM(B3),FIND(" ",TRIM(B3)&" ")-1))) -> 경기
A4: 구디가든카페 | B4: 경기 포천시 내촌면 매봉길 64-1 다동 1층 | C4: 0507-1443-1132 | D4: 0 | E4: 1 | F4: 0 | G4: 0 | H4: 0 | I4: 0 | J4: 1 | K4: 1 | L4: 1 | M4: 0 | N4: 0 | O4: 0 | P4: 실내 케이지 필수 | Q4: =IF(LEN(TRIM(B4))=0,"",IFERROR(VLOOKUP(LEFT(TRIM(B4),FIND(" ",TRIM(B4)&" ")-1),작성안내!$D$4:$E$23,2,FALSE),LEFT(TRIM(B4),FIND(" ",TRIM(B4)&" ")-1))) -> 경기
A5: 그리네 오아시스 | B5: 경기 포천시 소흘읍 죽엽산로 442 1층 | C5: 0507-1308-7428 | D5: 1 | E5: 1 | F5: 0 | G5: 0 | H5: 0 | I5: 0 | J5: 1 | K5: 1 | L5: 1 | M5: 0 | N5: 0 | O5: 0 | Q5: =IF(LEN(TRIM(B5))=0,"",IFERROR(VLOOKUP(LEFT(TRIM(B5),FIND(" ",TRIM(B5)&" ")-1),작성안내!$D$4:$E$23,2,FALSE),LEFT(TRIM(B5),FIND(" ",TRIM(B5)&" ")-1))) -> 경기
A6: 울미숲 | B6: 경기 포천시 군내면 꽃배산2길 107 | C6: 031-536-9077 | D6: 1 | E6: 1 | F6: 1 | G6: 1 | H6: 0 | I6: 0 | J6: 1 | K6: 1 | L6: 1 | M6: 0 | N6: 0 | O6: 0 | Q6: =IF(LEN(TRIM(B6))=0,"",IFERROR(VLOOKUP(LEFT(TRIM(B6),FIND(" ",TRIM(B6)&" ")-1),작성안내!$D$4:$E$23,2,FALSE),LEFT(TRIM(B6),FIND(" ",TRIM(B6)&" ")-1))) -> 경기
A7: 어반밸리 | B7: 경기 의정부시 호국로 952 1층 | C7: 0507-1468-1261 | D7: 1 | E7: 1 | F7: 0 | G7: 1 | H7: 0 | I7: 0 | J7: 1 | K7: 1 | L7: 1 | M7: 0 | N7: 0 | O7: 0 | Q7: =IF(LEN(TRIM(B7))=0,"",IFERROR(VLOOKUP(LEFT(TRIM(B7),FIND(" ",TRIM(B7)&" ")-1),작성안내!$D$4:$E$23,2,FALSE),LEFT(TRIM(B7),FIND(" ",TRIM(B7)&" ")-1))) -> 경기
A8: 테일즈업 | B8: 경기 의정부시 둔배미북길 14 | C8: 0507-1420-2232 | D8: 1 | E8: 1 | F8: 0 | G8: 1 | H8: 0 | I8: 0 | J8: 1 | K8: 1 | L8: 1 | M8: 0 | N8: 0 | O8: 0 | Q8: =IF(LEN(TRIM(B8))=0,"",IFERROR(VLOOKUP(LEFT(TRIM(B8),FIND(" ",TRIM(B8)&" ")-1),작성안내!$D$4:$E$23,2,FALSE),LEFT(TRIM(B8),FIND(" ",TRIM(B8)&" ")-1))) -> 경기
A9: 카페스토리 | B9: 경기 남양주시 와부읍 팔당로81번길 74-65 | C9: 0507-1367-5004 | D9: 1 | E9: 1 | F9: 0 | G9: 1 | H9: 0 | I9: 0 | J9: 1 | K9: 1 | L9: 1 | M9: 0 | N9: 0 | O9: 0 | Q9: =IF(LEN(TRIM(B9))=0,"",IFERROR(VLOOKUP(LEFT(TRIM(B9),FIND(" ",TRIM(B9)&" ")-1),작성안내!$D$4:$E$23,2,FALSE),LEFT(TRIM(B9),FIND(" ",TRIM(B9)&" ")-1))) -> 경기
A10: 레오나르독 | B10: 경기 양주시 은현면 은현로46번길 26 | C10: 0507-1444-8578 | D10: 1 | E10: 1 | F10: 1 | G10: 0 | H10: 0 | I10: 0 | J10: 1 | K10: 1 | L10: 1 | M10: 0 | N10: 0 | O10: 0 | Q10: =IF(LEN(TRIM(B10))=0,"",IFERROR(VLOOKUP(LEFT(TRIM(B10),FIND(" ",TRIM(B10)&" ")-1),작성안내!$D$4:$E$23,2,FALSE),LEFT(TRIM(B10),FIND(" ",TRIM(B10)&" ")-1))) -> 경기
A11: 카페 리버나인 | B11: 경기 남양주시 화도읍 북한강로 1630-18 1층 | C11: 010-3757-2805 | D11: 0 | E11: 1 | F11: 0 | G11: 1 | H11: 0 | I11: 0 | J11: 1 | K11: 1 | L11: 1 | M11: 0 | N11: 0 | O11: 0 | Q11: =IF(LEN(TRIM(B11))=0,"",IFERROR(VLOOKUP(LEFT(TRIM(B11),FIND(" ",TRIM(B11)&" ")-1),작성안내!$D$4:$E$23,2,FALSE),LEFT(TRIM(B11),FIND(" ",TRIM(B11)&" ")-1))) -> 경기
A12: 코니아일랜드 애견카페 | B12: 경기 남양주시 화도읍 북한강로 1627 | C12: 0507-1436-2394 | D12: 1 | E12: 1 | F12: 1 | G12: 0 | H12: 0 | I12: 0 | J12: 1 | K12: 1 | L12: 1 | M12: 0 | N12: 0 | O12: 0 | Q12: =IF(LEN(TRIM(B12))=0,"",IFERROR(VLOOKUP(LEFT(TRIM(B12),FIND(" ",TRIM(B12)&" ")-1),작성안내!$D$4:$E$23,2,FALSE),LEFT(TRIM(B12),FIND(" ",TRIM(B12)&" ")-1))) -> 경기
A13: 그루비독 애견카페 | B13: 경기 포천시 내촌면 소리개길 86-22 | C13: 0507-1308-4884 | D13: 1 | E13: 1 | F13: 1 | G13: 0 | H13: 0 | I13: 0 | J13: 1 | K13: 1 | L13: 1 | M13: 0 | N13: 0 | O13: 0 | Q13: =IF(LEN(TRIM(B13))=0,"",IFERROR(VLOOKUP(LEFT(TRIM(B13),FIND(" ",TRIM(B13)&" ")-1),작성안내!$D$4:$E$23,2,FALSE),LEFT(TRIM(B13),FIND(" ",TRIM(B13)&" ")-1))) -> 경기
A14: 루카 | B14: 경기 남양주시 진접읍 해밀예당2로 230 1층 | C14: 0507-1468-7083 | D14: 1 | E14: 1 | F14: 1 | G14: 0 | H14: 0 | I14: 0 | J14: 1 | K14: 1 | L14: 1 | M14: 0 | N14: 0 | O14: 0 | Q14: =IF(LEN(TRIM(B14))=0,"",IFERROR(VLOOKUP(LEFT(TRIM(B14),FIND(" ",TRIM(B14)&" ")-1),작성안내!$D$4:$E$23,2,FALSE),LEFT(TRIM(B14),FIND(" ",TRIM(B14)&" ")-1))) -> 경기
A15: 커멍하우스 | B15: 경기 의정부시 오목로15번길 2 1층 | C15: 0507-1354-6858 | D15: 0 | E15: 1 | F15: 0 | G15: 0 | H15: 0 | I15: 0 | J15: 1 | K15: 1 | L15: 0 | M15: 0 | N15: 1 | O15: 0 | Q15: =IF(LEN(TRIM(B15))=0,"",IFERROR(VLOOKUP(LEFT(TRIM(B15),FIND(" ",TRIM(B15)&" ")-1),작성안내!$D$4:$E$23,2,FALSE),LEFT(TRIM(B15),FIND(" ",TRIM(B15)&" ")-1))) -> 경기
A16: 함께라서 | B16: 경기 의정부시 부용로185번길 53 1층 | C16: 0507-1385-1323 | D16: 0 | E16: 1 | F16: 0 | G16: 0 | H16: 0 | I16: 0 | J16: 1 | K16: 1 | L16: 1 | M16: 0 | N16: 0 | O16: 0 | Q16: =IF(LEN(TRIM(B16))=0,"",IFERROR(VLOOKUP(LEFT(TRIM(B16),FIND(" ",TRIM(B16)&" ")-1),작성안내!$D$4:$E$23,2,FALSE),LEFT(TRIM(B16),FIND(" ",TRIM(B16)&" ")-1))) -> 경기
... A47: 타카이 | B47: 서울 강남구 학동로53길 19 1층 | C47: 0507-1455-0321 | D47: 0 | E47: 0 | F47: 0 | G47: 1 | H47: 0 | I47: 0 | J47: 1 | K47: 1 | L47: 0 | M47: 0 | N47: 0 | O47: 0 | Q47: =IF(LEN(TRIM(B47))=0,"",IFERROR(VLOOKUP(LEFT(TRIM(B47),FIND(" ",TRIM(B47)&" ")-1),작성안내!$D$4:$E$23,2,FALSE),LEFT(TRIM(B47),FIND(" ",TRIM(B47)&" ")-1))) -> 서울
A48: 더코너하우스 | B48: 서울 강남구 도산대로49길 6-7 1층 | C48: 0507-1394-5990 | D48: 0 | E48: 0 | F48: 0 | G48: 1 | H48: 0 | I48: 0 | J48: 1 | K48: 0 | L48: 1 | M48: 0 | N48: 0 | O48: 0 | P48: 테라스석 동반 가능 | Q48: =IF(LEN(TRIM(B48))=0,"",IFERROR(VLOOKUP(LEFT(TRIM(B48),FIND(" ",TRIM(B48)&" ")-1),작성안내!$D$4:$E$23,2,FALSE),LEFT(TRIM(B48),FIND(" ",TRIM(B48)&" ")-1))) -> 서울
A49: 오제 오징어제육 | B49: 서울 강남구 도산대로27길 40 1층 | C49: 0507-1404-3971 | D49: 0 | E49: 0 | F49: 0 | G49: 1 | H49: 0 | I49: 0 | J49: 0 | K49: 1 | L49: 0 | M49: 0 | N49: 0 | O49: 0 | Q49: =IF(LEN(TRIM(B49))=0,"",IFERROR(VLOOKUP(LEFT(TRIM(B49),FIND(" ",TRIM(B49)&" ")-1),작성안내!$D$4:$E$23,2,FALSE),LEFT(TRIM(B49),FIND(" ",TRIM(B49)&" ")-1))) -> 서울
A50: 모스가든 | B50: 서울 강남구 논현로139길 12 | C50: 0507-1489-1988 | D50: 0 | E50: 0 | F50: 0 | G50: 1 | H50: 0 | I50: 0 | J50: 1 | K50: 1 | L50: 0 | M50: 0 | N50: 0 | O50: 0 | Q50: =IF(LEN(TRIM(B50))=0,"",IFERROR(VLOOKUP(LEFT(TRIM(B50),FIND(" ",TRIM(B50)&" ")-1),작성안내!$D$4:$E$23,2,FALSE),LEFT(TRIM(B50),FIND(" ",TRIM(B50)&" ")-1))) -> 서울
A51: 구월의 소철 | B51: 서울 강남구 학동로 343 B1층 구월의소철 | C51: 0507-1417-3212 | D51: 0 | E51: 0 | F51: 0 | G51: 0 | H51: 1 | I51: 0 | J51: 1 | K51: 1 | L51: 0 | M51: 0 | N51: 0 | O51: 0 | P51: 룸 동반 가능 | Q51: =IF(LEN(TRIM(B51))=0,"",IFERROR(VLOOKUP(LEFT(TRIM(B51),FIND(" ",TRIM(B51)&" ")-1),작성안내!$D$4:$E$23,2,FALSE),LEFT(TRIM(B51),FIND(" ",TRIM(B51)&" ")-1))) -> 서울
A52: 파퓰러커피 | B52: 서울 강남구 학동로21길 6 | C52: 0507-1342-5064 | D52: 0 | E52: 1 | F52: 0 | G52: 0 | H52: 0 | I52: 0 | J52: 0 | K52: 1 | L52: 1 | M52: 0 | N52: 0 | O52: 0 | Q52: =IF(LEN(TRIM(B52))=0,"",IFERROR(VLOOKUP(LEFT(TRIM(B52),FIND(" ",TRIM(B52)&" ")-1),작성안내!$D$4:$E$23,2,FALSE),LEFT(TRIM(B52),FIND(" ",TRIM(B52)&" ")-1))) -> 서울
A53: 동대문대하구이사계절집 | B53: 서울 동대문구 장한로6길 53 102호 | C53: 0507-1370-4530 | D53: 0 | E53: 0 | F53: 0 | G53: 0 | H53: 1 | I53: 0 | J53: 1 | K53: 1 | L53: 0 | M53: 0 | N53: 0 | O53: 0 | P53: 소형견 가능 리드줄 필수 | Q53: =IF(LEN(TRIM(B53))=0,"",IFERROR(VLOOKUP(LEFT(TRIM(B53),FIND(" ",TRIM(B53)&" ")-1),작성안내!$D$4:$E$23,2,FALSE),LEFT(TRIM(B53),FIND(" ",TRIM(B53)&" ")-1))) -> 서울
A54: 신당육 | B54: 서울 중구 다산로46길 36 2층, 3층, 4층 | C54: 02-6953-8816 | D54: 0 | E54: 0 | F54: 0 | G54: 1 | H54: 1 | I54: 0 | J54: 1 | K54: 1 | L54: 1 | M54: 0 | N54: 0 | O54: 0 | P54: 소형견 가능 | Q54: =IF(LEN(TRIM(B54))=0,"",IFERROR(VLOOKUP(LEFT(TRIM(B54),FIND(" ",TRIM(B54)&" ")-1),작성안내!$D$4:$E$23,2,FALSE),LEFT(TRIM(B54),FIND(" ",TRIM(B54)&" ")-1))) -> 서울
A55: 심세정 | B55: 서울 중구 퇴계로 409-11 1층 | C55: 0507-1444-7579 | D55: 0 | E55: 1 | F55: 0 | G55: 0 | H55: 0 | I55: 0 | J55: 0 | K55: 0 | L55: 1 | M55: 0 | N55: 0 | O55: 0 | P55: 별관, 테라스 가능 | Q55: =IF(LEN(TRIM(B55))=0,"",IFERROR(VLOOKUP(LEFT(TRIM(B55),FIND(" ",TRIM(B55)&" ")-1),작성안내!$D$4:$E$23,2,FALSE),LEFT(TRIM(B55),FIND(" ",TRIM(B55)&" ")-1))) -> 서울
A56: 서울돼지구이 | B56: 서울 광진구 능동로 264 한사랑빌딩 1층 | C56: 0507-1336-1116 | D56: 0 | E56: 0 | F56: 0 | G56: 0 | H56: 1 | I56: 0 | J56: 1 | K56: 1 | L56: 0 | M56: 0 | N56: 0 | O56: 0 | P56: 유모차, 케이지 필수 | Q56: =IF(LEN(TRIM(B56))=0,"",IFERROR(VLOOKUP(LEFT(TRIM(B56),FIND(" ",TRIM(B56)&" ")-1),작성안내!$D$4:$E$23,2,FALSE),LEFT(TRIM(B56),FIND(" ",TRIM(B56)&" ")-1))) -> 서울
A57: Wnch동묘(운치) | B57: 서울 중구 청계천로 360 나동 104호 | C57: 0507-1330-8166 | D57: 0 | E57: 0 | F57: 0 | G57: 1 | H57: 1 | I57: 0 | J57: 1 | K57: 1 | L57: 0 | M57: 0 | N57: 0 | O57: 0 | Q57: =IF(LEN(TRIM(B57))=0,"",IFERROR(VLOOKUP(LEFT(TRIM(B57),FIND(" ",TRIM(B57)&" ")-1),작성안내!$D$4:$E$23,2,FALSE),LEFT(TRIM(B57),FIND(" ",TRIM(B57)&" ")-1))) -> 서울
A58: 전시회 | B58: 서울 동대문구 왕산로 131 2층 | C58: 0507-1394-8570 | D58: 0 | E58: 0 | F58: 0 | G58: 0 | H58: 1 | I58: 0 | J58: 1 | K58: 1 | L58: 1 | M58: 0 | N58: 0 | O58: 0 | P58: 케이지 필수 | Q58: =IF(LEN(TRIM(B58))=0,"",IFERROR(VLOOKUP(LEFT(TRIM(B58),FIND(" ",TRIM(B58)&" ")-1),작성안내!$D$4:$E$23,2,FALSE),LEFT(TRIM(B58),FIND(" ",TRIM(B58)&" ")-1))) -> 서울
A59: 오신돼지갈비 | B59: 서울 중구 다산로 232 1층 | C59: 0507-1357-9288 | D59: 0 | E59: 0 | F59: 0 | G59: 0 | H59: 1 | I59: 0 | J59: 1 | K59: 0 | L59: 1 | M59: 0 | N59: 0 | O59: 0 | P59: 소형견, 테라스 가능 | Q59: =IF(LEN(TRIM(B59))=0,"",IFERROR(VLOOKUP(LEFT(TRIM(B59),FIND(" ",TRIM(B59)&" ")-1),작성안내!$D$4:$E$23,2,FALSE),LEFT(TRIM(B59),FIND(" ",TRIM(B59)&" ")-1))) -> 서울
A60: 금뚜껑 | B60: 서울 성북구 동소문로22길 64 1층 | C60: 0507-1361-0997 | D60: 0 | E60: 0 | F60: 0 | G60: 0 | H60: 1 | I60: 0 | J60: 1 | K60: 1 | L60: 0 | M60: 0 | N60: 0 | O60: 0 | P60: 유모차, 케이지 필수 | Q60: =IF(LEN(TRIM(B60))=0,"",IFERROR(VLOOKUP(LEFT(TRIM(B60),FIND(" ",TRIM(B60)&" ")-1),작성안내!$D$4:$E$23,2,FALSE),LEFT(TRIM(B60),FIND(" ",TRIM(B60)&" ")-1))) -> 서울
A61: 피자빌리지 | B61: 서울 중랑구 봉우재로43길 12 1층 | C61: 0507-1448-1263 | D61: 0 | E61: 0 | F61: 0 | G61: 1 | H61: 0 | I61: 0 | J61: 0 | K61: 0 | L61: 1 | M61: 0 | N61: 0 | O61: 0 | P61: 테라스 가능 | Q61: =IF(LEN(TRIM(B61))=0,"",IFERROR(VLOOKUP(LEFT(TRIM(B61),FIND(" ",TRIM(B61)&" ")-1),작성안내!$D$4:$E$23,2,FALSE),LEFT(TRIM(B61),FIND(" ",TRIM(B61)&" ")-1))) -> 서울
A62: 메종 드 잠봉 | B62: 서울 성북구 동소문로22길 57-16 1층 | C62: 0507-1403-0031 | D62: 0 | E62: 0 | F62: 0 | G62: 1 | H62: 0 | I62: 0 | J62: 0 | K62: 0 | L62: 1 | M62: 0 | N62: 0 | O62: 0 | P62: 테라스 가능 | Q62: =IF(LEN(TRIM(B62))=0,"",IFERROR(VLOOKUP(LEFT(TRIM(B62),FIND(" ",TRIM(B62)&" ")-1),작성안내!$D$4:$E$23,2,FALSE),LEFT(TRIM(B62),FIND(" ",TRIM(B62)&" ")-1))) -> 서울
A63: 운치 | B63: 서울 성북구 고려대로7길 48 1층 | C63: 0507-1475-4644 | D63: 0 | E63: 0 | F63: 0 | G63: 1 | H63: 0 | I63: 0 | J63: 1 | K63: 1 | L63: 1 | M63: 0 | N63: 0 | O63: 0 | Q63: =IF(LEN(TRIM(B63))=0,"",IFERROR(VLOOKUP(LEFT(TRIM(B63),FIND(" ",TRIM(B63)&" ")-1),작성안내!$D$4:$E$23,2,FALSE),LEFT(TRIM(B63),FIND(" ",TRIM(B63)&" ")-1))) -> 서울
A64: 누리담 | B64: 서울 중구 퇴계로81길 10 1층 | C64: 0507-1386-3922 | D64: 0 | E64: 0 | F64: 0 | G64: 0 | H64: 1 | I64: 0 | J64: 0 | K64: 1 | L64: 0 | M64: 0 | N64: 0 | O64: 0 | Q64: =IF(LEN(TRIM(B64))=0,"",IFERROR(VLOOKUP(LEFT(TRIM(B64),FIND(" ",TRIM(B64)&" ")-1),작성안내!$D$4:$E$23,2,FALSE),LEFT(TRIM(B64),FIND(" ",TRIM(B64)&" ")-1))) -> 서울
A65: 보메청담 | B65: 서울 중구 퇴계로 461 1층 101호 | C65: 02-2233-0937 | D65: 0 | E65: 0 | F65: 0 | G65: 1 | H65: 0 | I65: 0 | J65: 1 | K65: 1 | L65: 1 | M65: 0 | N65: 0 | O65: 0 | P65: 유모차, 케이지 필수 | Q65: =IF(LEN(TRIM(B65))=0,"",IFERROR(VLOOKUP(LEFT(TRIM(B65),FIND(" ",TRIM(B65)&" ")-1),작성안내!$D$4:$E$23,2,FALSE),LEFT(TRIM(B65),FIND(" ",TRIM(B65)&" ")-1))) -> 서울
A66: 펫터니아 하우스 | B66: 서울 성북구 고려대로1길 69 1층 | C66: 0507-1334-2014 | D66: 0 | E66: 1 | F66: 0 | G66: 0 | H66: 0 | I66: 0 | J66: 1 | K66: 1 | L66: 1 | M66: 0 | N66: 0 | O66: 0 | Q66: =IF(LEN(TRIM(B66))=0,"",IFERROR(VLOOKUP(LEFT(TRIM(B66),FIND(" ",TRIM(B66)&" ")-1),작성안내!$D$4:$E$23,2,FALSE),LEFT(TRIM(B66),FIND(" ",TRIM(B66)&" ")-1))) -> 서울
Q67: =IF(LEN(TRIM(B67))=0,"",IFERROR(VLOOKUP(LEFT(TRIM(B67),FIND(" ",TRIM(B67)&" ")-1),작성안내!$D$4:$E$23,2,FALSE),LEFT(TRIM(B67),FIND(" ",TRIM(B67)&" ")-1)))
Q68: =IF(LEN(TRIM(B68))=0,"",IFERROR(VLOOKUP(LEFT(TRIM(B68),FIND(" ",TRIM(B68)&" ")-1),작성안내!$D$4:$E$23,2,FALSE),LEFT(TRIM(B68),FIND(" ",TRIM(B68)&" ")-1)))
Q69: =IF(LEN(TRIM(B69))=0,"",IFERROR(VLOOKUP(LEFT(TRIM(B69),FIND(" ",TRIM(B69)&" ")-1),작성안내!$D$4:$E$23,2,FALSE),LEFT(TRIM(B69),FIND(" ",TRIM(B69)&" ")-1)))
Q70: =IF(LEN(TRIM(B70))=0,"",IFERROR(VLOOKUP(LEFT(TRIM(B70),FIND(" ",TRIM(B70)&" ")-1),작성안내!$D$4:$E$23,2,FALSE),LEFT(TRIM(B70),FIND(" ",TRIM(B70)&" ")-1)))
...

Sheet 작성안내
A1: 업체정보 입력 양식 · 작성 안내
A3: 입력 방법 | B3: 「업체정보」 시트 2행부터 업체 한 곳당 한 줄씩 입력하세요. 빈 입력란 100개를 준비했습니다. | D3: 주소의 시·도 표기 | E3: 지역
A4: 파일 관리 | B4: 이 파일을 복사해 업체정보_2026-10-16.xlsx처럼 저장하세요. 같은 업체 수정 시 기존 행을 수정하고, 중복 행을 만들지 마세요. | D4: 서울특별시 | E4: 서울
A5: 기본 필수 항목 | B5: 상호명, 주소, 해당 카테고리 1개 이상을 입력하세요. 연락처는 확인된 경우 입력하세요. | D5: 부산광역시 | E5: 부산
A6: 카테고리 선택 | B6: D~I열: 해당하면 1, 아니면 0 입력 후 Tab. 화면에는 예/아니오로 표시됩니다. 여러 카테고리에 1을 입력할 수 있습니다. | D6: 대구광역시 | E6: 대구
A7: 운동장카페 | B7: 반려견이 이용할 수 있는 운동장을 갖춘 카페. 동반 카페에도 해당하면 두 열 모두 「예」를 선택하세요. | D7: 인천광역시 | E7: 인천
A8: 동반 카페 | B8: 반려견과 함께 방문할 수 있다고 확인한 카페. | D8: 광주광역시 | E8: 광주
A9: 대형견카페 | B9: 대형견 이용이 가능하다고 확인한 카페. 운동장카페 또는 동반 카페와 함께 선택할 수 있습니다. | D9: 대전광역시 | E9: 대전
A10: 동반 음식점 | B10: 반려견 동반이 가능하다고 확인한 음식점. | D10: 울산광역시 | E10: 울산
A11: 동반 술집 | B11: 반려견 동반이 가능하다고 확인한 술집. | D11: 세종특별자치시 | E11: 세종
A12: 동반 펜션 | B12: 반려견 동반이 가능하다고 확인한 펜션. | D12: 경기도 | E12: 경기
A13: 조건 필터 | B13: J~L열: 주차가능 / 실내 동반 / 테라스 동반. 가능하면 1, 불가하면 0 입력 후 Tab. 미확인은 빈칸 또는 미확인으로 입력하세요. | D13: 강원도 | E13: 강원
A14: 모르는 정보 | B14: 조건을 확인하지 못했으면 「미확인」 또는 빈칸으로 두세요. 「불가」와 구분해 주세요. 연락처·영업시간도 추측하지 마세요. | D14: 강원특별자치도 | E14: 강원
... A23: 사이트 반영 | B23: 현재는 폴더에 파일을 넣는 것만으로 사이트에 자동 반영되지 않습니다. 엑셀 읽기·데이터 변환·배포 연결을 별도로 구현해야 합니다. | D23: 제주도 | E23: 제주
A24: 양식 범위 | B24: 이 파일은 입력 양식입니다. 실제 업체 데이터는 포함하지 않았습니다. 동반 펜션의 사이트 카테고리 연결도 추후 구현이 필요합니다.
A25: 빠른 입력 | B25: 1 = 예·가능 / 0 = 아니오·불가. Tab은 다음 칸, Shift+Tab은 이전 칸입니다. 빈칸은 미입력입니다.
A26: 지역 검색 | B26: 업체정보 시트 N열 지역의 필터에서 서울·대전·대구·부산 등을 선택하세요. 주소를 입력하면 지역이 자동으로 표시됩니다.
A27: 상호명·주소 검색 | B27: 각 제목 오른쪽 필터에서 검색하거나 텍스트 필터 → 포함을 사용하세요. 필터 지우기로 전체 목록을 다시 표시합니다.
